Workbook

Sheet A
A3: Etiquetas de fila | B3: Suma de mar-25 | C3: Suma de TOTAL COBROS Y RESERVAS | H3: Etiquetas de fila | I3: Suma de mar-25 | J3: Suma de Total de Cobro Ppto | K3: Suma de TOTAL COBROS Y RESERVAS | L3: Suma de Variación ppto versus cobro real | N3: Etiquetas de fila | O3: Suma de mar-25 | P3: Suma de TOTAL COBROS Y RESERVAS
A4: Cliente Atrasado | B4: 25000 | C4: 1741825.6 | H4: Cliente al día | I4: 15961.42 | J4: 199192.64 | K4: 199192.64 | L4: 0 | N4: Cliente Atrasado | O4: 943639.33 | P4: 14614695
A5: Enganche Completado | B5: 20500 | C5: 3579629 | H5: Cliente atrasado | I5: 15293.08 | J5: 435504.98 | K5: 272644.18 | L5: 162860.8 | N5: Enganche Completado | O5: 29962 | P5: 1202813.2
A6: Superávit de Enganche | B6: 3740366 | C6: 10330693 | H6: Cliente disponible | J6: 0 | K6: 0 | L6: 0 | N6: Disponible | O6: 0 | P6: 0
A7: Disponible | B7: 0 | C7: 0 | H7: Pendiente plan de pagos | J7: 0 | K7: 1500 | L7: -1500 | N7: Superávit de Enganche | O7: 50500 | P7: 1330269
A8: Total general | B8: 3785866 | C8: 15652148 | H8: Superavit de enganche | I8: 15857.17 | J8: 146846.17 | K8: 155646.01 | L8: -8799.84 | N8: Total general | O8: 1024101.3 | P8: 17147777
H9: Total general | I9: 47111.67 | J9: 781543.79 | K9: 628982.83 | L9: 152560.96
A16: En cada tabla colocar el mes que corresponda para poder llevar bien la estadistica

Sheet B
A3: Etiquetas de fila | B3: Cuenta de Apto | C3: Suma de TOTAL COBROS Y RESERVAS | I3: Etiquetas de fila | J3: Suma de feb-25 | K3: Cuenta de Apto | L3: Suma de Total de Cobro Ppto | M3: Suma de TOTAL COBROS Y RESERVAS | N3: Suma de Variación ppto versus cobro real | R3: Etiquetas de fila | S3: Cuenta de Apto | T3: Suma de TOTAL COBROS Y RESERVAS
A4: Cliente Atrasado | B4: 11 | C4: 1741825.6 | I4: Cliente al día | J4: 17160.23 | K4: 11 | L4: 199192.64 | M4: 199192.64 | N4: 0 | R4: Cliente Atrasado | S4: 244 | T4: 14614695
A5: Enganche Completado | B5: 17 | C5: 3579629 | I5: Cliente atrasado | J5: 16376.42 | K5: 26 | L5: 435504.98 | M5: 272644.18 | N5: 162860.8 | R5: Enganche Completado | S5: 4 | T5: 1202813.2
A6: Superávit de Enganche | B6: 46 | C6: 10330693 | I6: Cliente disponible | J6: 0 | K6: 30 | L6: 0 | M6: 0 | N6: 0 | R6: Disponible | S6: 46 | T6: 0
A7: Disponible | B7: 1 | C7: 0 | I7: Pendiente plan de pagos | J7: 1500 | K7: 1 | L7: 0 | M7: 1500 | N7: -1500 | R7: Superávit de Enganche | S7: 4 | T7: 1330269
A8: Total general | B8: 75 | C8: 15652148 | I8: Superavit de enganche | J8: 16773.37 | K8: 10 | L8: 146846.17 | M8: 155646.01 | N8: -8799.84 | R8: Total general | S8: 298 | T8: 17147777
I9: Total general | J9: 51810.02 | K9: 78 | L9: 781543.79 | M9: 628982.83 | N9: 152560.96

Sheet C
A4: Etiquetas de fila | B4: Suma de mar-25 | C4: Suma de Acumulado | F4: Etiquetas de fila | G4: Suma de mar-25 | H4: Suma de Acumulado | K4: Etiquetas de fila | L4: Suma de mar-25 | M4: Suma de b
A5: 0 | C5: 2322161.9 | F5: 0 | G5: 2228.57 | H5: 27742.84 | K5: 0 | L5: 1346050.5 | M5: 18963742
A6: -5000 | C6: 676200 | F6: 459835.32 | G6: 1022.73 | H6: 12750.03 | K6: Total general | L6: 1346050.5 | M6: 18963742
A7: 111875 | C7: 900000 | F7: 463755.6 | G7: 1244.44 | H7: 12699.96
A8: 3520.45 | C8: 770000 | F8: 458927.83 | G8: 1045.45 | H8: 14090.85
A9: 725400 | C9: 80600 | F9: 494900 | H9: 23899.94
A10: 652330.22 | C10: 81400 | F10: 346215 | G10: 1784.29 | H10: 29548.64
A11: 1201700 | C11: 63300 | F11: #N/D | G11: 1875 | H11: 5250
A12: 1045100 | C12: 55100 | F12: 448214.94 | G12: 2434.74 | H12: 42185.84
A13: 575700 | C13: 64000 | F13: 477700 | G13: 1125 | H13: 13875
A14: 645000 | B14: 645000 | C14: 650000 | F14: 461012 | G14: 1045.45 | H14: 12499.95
A15: 705400 | C15: 100000 | F15: 452581.8 | G15: 2240.91 | H15: 36354.56
A16: 689591.49 | C16: 84000 | F16: 463588.23 | G16: 1323.53 | H16: 12088.24
A17: 445693.09 | C17: 37100 | F17: 460317.64 | G17: 1323.53 | H17: 12088.24
A18: 435029.72 | C18: 173320 | F18: 349636.4 | G18: 1704.55 | H18: 28272.8
A19: 923800 | C19: 47500 | F19: 450159 | G19: 2374.5 | H19: 40866.5
A20: 468690.28 | C20: 38500 | F20: 507200 | H20: 0
A21: 650000 | C21: 0 | F21: 474706 | H21: 0
A22: 309477.87 | C22: 58000 | F22: 474100 | H22: 14100
A23: 717500 | C23: 166000 | F23: 463438.44 | G23: 1723.08 | H23: 6669.24
A24: 546878.68 | C24: 48066 | F24: 461200 | G24: 1493.33 | H24: 10459.98
A25: 456605.45 | C25: 130000 | F25: 486200 | H25: 0
A26: 915700 | C26: 47500 | F26: 956042 | H26: 0
A27: 590900 | C27: 40500 | F27: 486950 | G27: 1125 | H27: 13875
A28: 615000 | C28: 68000 | F28: 505700 | H28: 0
A29: 483000 | C29: 54780 | F29: 459100 | H29: 0
A30: 422900 | C30: 70390 | F30: 452400.06 | G30: 2333.33 | H30: 35499.95
A31: 942821 | C31: 0 | F31: 473200 | H31: 23900
A32: 589500 | C32: 65500 | F32: 462530 | G32: 1178.95 | H32: 13289.5
A33: 175000 | C33: 414500 | F33: 365237.5 | H33: 0
A34: 899300 | C34: 49500 | F34: 394300 | H34: 0
A35: 488991.83 | C35: 68000 | F35: 476200 | G35: 1229.5 | H35: 29124.5
A36: 492984.65 | C36: 54780 | F36: 460275 | H36: 24000.04
A37: 335086.45 | C37: 54700 | F37: 487200 | H37: 0
A38: 497324.27 | C38: 68800 | F38: 505237.5 | G38: 2323.81 | H38: 35857.15
A39: 930000 | C39: 49500 | F39: 362637.5 | G39: 1062.5 | H39: 15312.5
A40: 403500 | C40: 66500 | F40: 475500 | H40: 0
A41: 764500 | C41: 40500 | F41: 461526.16 | G41: 2436.84 | H41: 39489.44
A42: 869929.1 | C42: 47500 | F42: 474700 | H42: 0
A43: 445000 | C43: 69000 | F43: 460805.27 | H43: 0
...

Sheet RESUMEN
B2: DESARROLLOS INMOBILIARIOS
B3: RESUMEN DE COBROS POR PROYECTOS
B5: Al mes de : | C5: 45900
F6: ( + ) | G6: ( - ) | K6: ( + ) A | L6: ( - ) B | M6: ( = ) C | O6: ( + ) D | P6: ( - ) E | R6: ( C ) - (D-E) | V6: ( + ) | W6: ( - )
B7: Proyecto | C7: PPTO del mes | D7: Cobro del mes | E7: % de cobro del mes | F7: Ppto Acumulado | G7: Cobros Acumulados | H7: % de cobros acumulado | I7: Total cobros pendientes | K7: Efectivo acum. que se debió recibir | L7: Cobros por Efectuar (Casos Especiales / F&F) | M7: Cobros Netos Acumulados | O7: Cobros realizados | P7: Cobros Adicionales | R7: Saldo Conciliado | S7: Cobros por Efectuar (Clientes en Mora) | T7: Diferencia | V7: Cobros (Desistimientos) | W7: Devoluciones (Desistimientos) | Y7: (Faltante) / Sobrante en Flujo de Caja
B8: Casa Elisa | C8: =+'SANTA ELISA PPTO'!AL80 -> 0 | D8: =+'SANTA ELISA'!AV80 -> 0 | E8: =IFERROR((+D8/C8),0) -> 0 | F8: =+'SANTA ELISA PPTO'!AL81 -> 10097247 | G8: =+'SANTA ELISA PPTO'!AM80 -> 10097247 | H8: =IFERROR((+G8/F8),0) -> 1 | I8: =+F8-G8 -> 0
B9: Gran Jaguar | C9: =+'BOULEVARD PPTO'!AE311 -> 2967923.5 | D9: =+'BOULEVARD 5'!AM305-'BOULEVARD 5'!AM254-'BOULEVARD 5'!AM266 -> 3072696.4 | E9: =IFERROR((+D9/C9),0) -> 1.0353018 | F9: =+'BOULEVARD PPTO'!AE313 -> 23321517 | G9: =+'BOULEVARD 5'!AT305-612138 -> 30721735 | H9: =IFERROR((+G9/F9),0) -> 1.3173129 | I9: =+F9-G9 -> -7400218.6 | K9: =+'BOULEVARD 5'!BJ305 -> #VALUE! | L9: =+'BOULEVARD 5'!BO306 -> 2682559 | M9: =+K9-L9 -> #VALUE! | O9: =+'BOULEVARD 5'!BK305+'BOULEVARD 5'!BL305+'BOULEVARD 5'!BM305 -> 31333873 | P9: =+'BOULEVARD 5'!BN305 -> #VALUE! | R9: =((M9)-(O9-P9)) -> #VALUE! | S9: =+'BOULEVARD 5'!BO305-+'BOULEVARD 5'!BO306 -> #VALUE! | T9: =+R9-S9 -> #VALUE! | V9: =+'BOULEVARD 5'!AT306 -> 874279.14 | W9: 177175.45 | Y9: =-R9+V9-W9 -> #VALUE!
B10: Chinautla | C10: =+'BENESTARE PPTO'!AE115 -> 105339.09 | D10: =+'BENESTARE '!AQ174 -> 101165.69 | E10: =IFERROR((+D10/C10),0) -> 0.96038128 | F10: =+'BENESTARE PPTO'!AE116 -> 957782.27 | G10: =+'BENESTARE '!AX174 -> 1478044.7 | H10: =IFERROR((+G10/F10),0) -> 1.5431949 | I10: =+F10-G10 -> -520262.4 | K10: =+BENES!BD87 -> #NUM! | L10: =+BENES!BI88 -> 0 | M10: =+K10-L10 -> #NUM! | O10: =+BENES!BE87+BENES!BF87+BENES!BG87 -> 841408.68 | P10: =+BENES!BH87 -> #NUM! | R10: =((M10)-(O10-P10)) -> #NUM! | S10: =+BENES!BI87 -> #NUM! | T10: =+R10-S10 -> #NUM! | V10: =+BENES!AN88 -> 100416.23 | Y10: =-R10+V10-W10 -> #NUM!
B11: Bosque Las T. | C11: =+'BL PPTO'!AE120 -> 54685.15 | D11: =+'BL-TAPIAS'!O124 -> 53271.38 | E11: =IFERROR((+D11/C11),0) -> 0.97414709 | F11: =+'BL PPTO'!AE123 -> 95544.37 | G11: =+'BL-TAPIAS'!V124 -> 545624.27 | H11: =IFERROR((+G11/F11),0) -> 5.7106899 | I11: =+F11-G11 -> -450079.9 | K11: =+'BL-TAPIAS'!AL124 -> 163461.59 | L11: =+'BL-TAPIAS'!AQ125 -> 0 | M11: =+K11-L11 -> 163461.59 | O11: =+'BL-TAPIAS'!AM124+'BL-TAPIAS'!AN124+'BL-TAPIAS'!AO124 -> 545624.27 | P11: =+'BL-TAPIAS'!AP124 -> 388329.36 | R11: =((M11)-(O11-P11)) -> 6166.68 | S11: =+'BL-TAPIAS'!AQ124 -> 6171.68 | T11: =+R11-S11 -> -5 | V11: =+'BL-TAPIAS'!V125 -> 8000 | Y11: =-R11+V11-W11 -> 1833.32
C12: =SUM(C8:C11) -> 3127947.7 | D12: =SUM(D8:D11) -> 3227133.5 | E12: =IFERROR((+D12/C12),0) -> 1.0317095 | F12: =SUM(F8:F11) -> 34472091 | G12: =SUM(G8:G11) -> 42842652 | H12: =IFERROR((+G12/F12),0) -> 1.2428214 | I12: =SUM(I8:I11) -> -8370560.9 | K12: =SUM(K8:K11) -> #VALUE! | L12: =SUM(L8:L11) -> 2682559 | M12: =SUM(M8:M11) -> #VALUE! | O12: =SUM(O8:O11) -> 32720906 | P12: =SUM(P8:P11) -> #VALUE! | R12: =SUM(R8:R11) -> #VALUE! | S12: =SUM(S8:S11) -> #VALUE! | T12: =SUM(T8:T11) -> #VALUE! | V12: =SUM(V8:V11) -> 982695.37 | W12: =SUM(W8:W11) -> 177175.45 | Y12: =SUM(Y8:Y11) -> #VALUE!
L13: =+I9-L9 -> -10082778
B14: Proyecto | C14: Total Apartamentos | D14: Cliente al día | E14: Cliente atrasado | F14: Disponible | G14: Enganche completado | H14: Superávit de Enganche | I14: F&F
B15: Casa Elisa | C15: =COUNTA('SANTA ELISA'!B5:B79) -> 75 | D15: =COUNTIF('SANTA ELISA'!$BG$5:$BG$79,D$14) -> 0 | E15: =COUNTIF('SANTA ELISA'!$BG$5:$BG$79,E$14) -> 11 | F15: =COUNTIF('SANTA ELISA'!$BG$5:$BG$79,F$14) -> 1 | G15: =COUNTIF('SANTA ELISA'!$BG$5:$BG$79,G$14) -> 17 | H15: =COUNTIF('SANTA ELISA'!$BG$5:$BG$79,H$14) -> 46 | I15: =COUNTIF('SANTA ELISA'!$BG$5:$BG$79,I$14) -> 0
B16: Gran Jaguar | C16: =COUNTA('BOULEVARD 5'!B7:B304) -> 298 | D16: =COUNTIF('BOULEVARD 5'!$BB:$BB,D$14) -> 61 | E16: =COUNTIF('BOULEVARD 5'!BB:BB,E14)-I16 -> 159 | F16: =COUNTIF('BOULEVARD 5'!$BB:$BB,F$14) -> 14 | G16: =COUNTIF('BOULEVARD 5'!$BB:$BB,G$14) -> 7 | H16: =COUNTIF('BOULEVARD 5'!BB:BB,H$14) -> 30 | I16: =COUNTIFS('BOULEVARD 5'!$BB:$BB,E$14,'BOULEVARD 5'!BQ:BQ,$I14) -> 26
B17: Chinautla | C17: =COUNTA(BENES!B7:B86) -> 80 | D17: =COUNTIF(BENES!$AV:$AV,D$14) -> 36 | E17: =COUNTIF(BENES!$AV:$AV,E$14) -> 17 | F17: =COUNTIF(BENES!$AV:$AV,F$14) -> 16 | G17: =COUNTIF(BENES!$AV:$AV,G$14) -> 0 | H17: =COUNTIF(BENES!$AV:$AV,H$14) -> 0 | I17: =COUNTIFS(BENES!$AV:$AV,E$14,BENES!BK:BK,$I14) -> 0
B18: Bosque Las T. | C18: =COUNTA('BL-TAPIAS'!B7:B123) -> 117 | D18: =COUNTIF('BL-TAPIAS'!$AD:$AD,D$14) -> 61 | E18: =COUNTIF('BL-TAPIAS'!$AD:$AD,E$14) -> 5 | F18: =COUNTIF('BL-TAPIAS'!$AD:$AD,F$14) -> 51 | G18: =COUNTIF('BL-TAPIAS'!$AD:$AD,G$14) -> 0 | H18: =COUNTIF('BL-TAPIAS'!$AD:$AD,H$14) -> 0 | I18: =COUNTIFS('BL-TAPIAS'!$AD:$AD,E$14,'BL-TAPIAS'!AS:AS,$I14) -> 0
C19: =SUM(C15:C18) -> 570 | D19: =SUM(D15:D18) -> 158 | E19: =SUM(E15:E18) -> 192 | F19: =SUM(F15:F18) -> 82 | G19: =SUM(G15:G18) -> 24 | H19: =SUM(H15:H18) -> 76 | I19: =SUM(I15:I18) -> 26
B22: % de las cantidades
B23: Proyecto | C23: Total Apartamentos | D23: Cliente al día | E23: Cliente atrasado | F23: Cliente Disponible | G23: Enganche completado | H23: Superávit de Enganche | I23: F&F
B24: Casa Elisa | C24: 1 | D24: =+D15/$C$15 -> 0 | E24: =+E15/$C$15 -> 0.14666667 | F24: =+F15/$C$15 -> 0.013333333 | G24: =+G15/$C$15 -> 0.22666667 | H24: =+H15/$C$15 -> 0.61333333 | I24: =+I15/$C$15 -> 0
B25: Gran Jaguar | C25: 1 | D25: =+D16/$C$16 -> 0.20469799 | E25: =+E16/$C$16 -> 0.53355705 | F25: =+F16/$C$16 -> 0.046979866 | G25: =+G16/$C$16 -> 0.023489933 | H25: =+H16/$C$16 -> 0.10067114 | I25: =+I16/$C$16 -> 0.087248322
B26: Chinautla | C26: 1 | D26: =+D17/$C$17 -> 0.45 | E26: =+E17/$C$17 -> 0.2125 | F26: =+F17/$C$17 -> 0.2 | G26: =+G17/$C$17 -> 0 | H26: =+H17/$C$17 -> 0 | I26: =+I17/$C$17 -> 0
B27: Bosque Las T. | C27: 1 | D27: =+D18/$C$18 -> 0.52136752 | E27: =+E18/$C$18 -> 0.042735043 | F27: =+F18/$C$18 -> 0.43589744 | G27: =+G18/$C$18 -> 0 | H27: =+H18/$C$18 -> 0 | I27: =+I18/$C$18 -> 0
C28: =AVERAGE(C24:C27) -> 1 | D28: =AVERAGE(D24:D27) -> 0.29401638 | E28: =AVERAGE(E24:E27) -> 0.23386469 | F28: =AVERAGE(F24:F27) -> 0.17405266 | G28: =AVERAGE(G24:G27) -> 0.06253915 | H28: =AVERAGE(H24:H27) -> 0.17850112 | I28: =AVERAGE(I24:I27) -> 0.021812081

Sheet Detalle2
A1: Detalles para Cobro no realizado. - Apto: 315, Cuotas: 2, ESTATUS CLIENTE: Cliente Atrasado
A3: Apto | B3: Tipo | C3: NOTAS | D3: Vendedor | E3: Cliente | F3: Reservado | G3: Estatus | H3: Precio de Venta | I3: Enganche | J3: mar-23 | K3: abr-23 | L3: may-23 | M3: jun-23 | N3: jul-23 | O3: ago-23 | P3: sep-23 | Q3: oct-23 | R3: nov-23 | S3: dic-23 | T3: ene-24 | U3: feb-24 | V3: mar-24 | W3: abr-24 | X3: may-24 | Y3: jun-24 | Z3: jul-24 | AA3: ago-24 | AB3: sep-24 | AC3: oct-24 | AD3: nov-24 | AE3: dic-24 | AF3: ene-25 | AG3: feb-25 | AH3: mar-25 | AI3: abr-25 | AJ3: may-25 | AK3: jun-25 | AL3: jul-25 | AM3: ago-25 | AN3: TOTAL COBROS Y RESERVAS | AO3: % Cobro | AP3: SALDO PENDIENTE ENGANCHE | AQ3: % Pendiente | AR3: Monto a Financiar por Banco | AS3: % a Financiar | AT3: Proyección de Cobros (S/ Modelo Financiero) | AU3: Status inmueble | AV3: ESTATUS CLIENTE | AW3: Cuotas Pactadas | AX3: Cuota de Enganche | AY3: Total cuotas pactadas | AZ3: Monto de Reserva Pactado | BA3: Monto de Cuota Pactada | BB3: Cuotas Pagadas | BC3: Cantidad de cuotas que deben estar pagadas por el cliente | BD3: Monto que debe estar cancelado a la fecha | BE3: Monto pagado de cuotas a la fecha | BF3: Enganche + Cuotas Extraordinarias Pagadas | BG3: Diferencia | BH3: Cobro adicional a lo pactado | BI3: Cobro no realizado según lo pactado | BJ3: Cuotas | BK3: Caso Especial / F&F | BL3: Observaciones
A4: 315 | B4: E1 | D4: Sofia Paredes | E4: Lilian America Roldan Ochoa | F4: 45752 | G4: 4.Plan de pagos | H4: 1543627 | I4: 154426.97 | J4: 0 | K4: 0 | L4: 0 | M4: 0 | N4: 0 | O4: 0 | P4: 0 | Q4: 0 | R4: 0 | S4: 0 | T4: 0 | U4: 0 | V4: 0 | W4: 0 | X4: 0 | Y4: 0 | Z4: 0 | AA4: 0 | AB4: 0 | AC4: 0 | AD4: 0 | AE4: 0 | AF4: 0 | AG4: 0 | AH4: 0 | AI4: 10000 | AJ4: 10000 | AL4: 10024 | AN4: 30024 | AO4: 0.194422 | AP4: -124402.97 | AQ4: -0.805578 | AR4: 1513603 | AS4: 0.9805497 | AT4: 154426.97 | AU4: Vendido | AV4: Cliente Atrasado | AW4: 13 | AX4: 1 | AY4: 14 | AZ4: 10000 | BA4: 11110 | BB4: 0 | BC4: 3 | BD4: 43330 | BE4: 30024 | BF4: 0 | BG4: 0 | BH4: 0 | BI4: 13306 | BJ4: 2

Sheet Detalle3
A1: Detalles para Cobro no realizado. - Apto.: 602, Cuotas: 2, ESTATUS CLIENTE: Cliente Atrasado
A3: Apto. | B3: Tipo. | C3: NOTAS | D3: Vendedor | E3: Cliente | F3: Fecha Reserva | G3: Estatus | H3: Precio de Venta | I3: Enganche | J3: mar-23 | K3: abr-23 | L3: may-23 | M3: jun-23 | N3: jul-23 | O3: ago-23 | P3: sep-23 | Q3: oct-23 | R3: nov-23 | S3: dic-23 | T3: ene-24 | U3: feb-24 | V3: mar-24 | W3: abr-24 | X3: may-24 | Y3: jun-24 | Z3: jul-24 | AA3: ago-24 | AB3: sep-24 | AC3: oct-24 | AD3: nov-24 | AE3: dic-24 | AF3: ene-25 | AG3: feb-25 | AH3: mar-25 | AI3: abr-25 | AJ3: may-25 | AK3: jun-25 | AL3: jul-25 | AM3: ago-25 | AN3: TOTAL COBROS Y RESERVAS | AO3: % Cobro | AP3: SALDO PENDIENTE ENGANCHE | AQ3: % Pendiente | AR3: Monto a Financiar por Banco | AS3: % a Financiar | AT3: Proyección de Cobros (S/ Modelo Financiero) | AU3: Status inmueble | AV3: ESTATUS CLIENTE | AW3: Cuotas Pactadas | AX3: Cuota de Enganche | AY3: Total cuotas pactadas | AZ3: Monto de Reserva Pactado | BA3: Monto de Cuota Pactada | BB3: Cuotas Pagadas | BC3: Cantidad de cuotas que deben estar pagadas por el cliente | BD3: Monto que debe estar cancelado a la fecha | BE3: Monto pagado de cuotas a la fecha | BF3: Enganche + Cuotas Extraordinarias Pagadas | BG3: Diferencia | BH3: Cobro adicional a lo pactado | BI3: Cobro no realizado según lo pactado | BJ3: Cuotas | BK3: Caso Especial / F&F | BL3: Observaciones
A4: 602 | B4: E10 | D4: Anahí Cisneros | E4: Judith Fabiola Arevalo Valdez de Franco | F4: 45815 | G4: 2. Reserva | H4: 1529194.3 | I4: 152894.33 | J4: 0 | K4: 0 | L4: 0 | M4: 0 | N4: 0 | O4: 0 | P4: 0 | Q4: 0 | R4: 0 | S4: 0 | T4: 0 | U4: 0 | V4: 0 | W4: 0 | X4: 0 | Y4: 0 | Z4: 0 | AA4: 0 | AB4: 0 | AC4: 0 | AD4: 0 | AE4: 0 | AF4: 0 | AG4: 0 | AH4: 0 | AI4: 0 | AK4: 10000 | AN4: 10000 | AO4: 0.065404649 | AP4: -142894.33 | AQ4: -0.93459535 | AR4: 1519194.3 | AS4: 0.99346061 | AT4: 152894.33 | AU4: Vendido | AV4: Cliente Atrasado | AW4: 12 | AX4: 1 | AY4: 13 | AZ4: 10000 | BA4: 11908 | BB4: 0 | BC4: 2 | BD4: 33816 | BE4: 10000 | BF4: 0 | BG4: 0 | BH4: 0 | BI4: 23816 | BJ4: 2

Sheet ALERTA (B5)
F2: RESUMEN
C3: PROYECTO: | D3: GRAN JAGUAR
C4: ESTATUS CLIENTE | D4: Cliente Atrasado
C6: Cuotas | D6: Apto. | E6: Cobro no realizado.
C7: 1 | D7: 104 | E7: 1824
D8: 109 | E8: 7704
D9: 110 | E9: 2388
D10: 111 | E10: 820
D11: 312 | E11: 7851
D12: 404 | E12: 2791
D13: 410 | E13: 5.46
D14: 505 | E14: 7645
D15: 506 | E15: 450
D16: 508 | E16: 6404
D17: 510 | E17: 1868
D18: 512 | E18: 2477
D19: 513 | E19: 2415
... D51: 1609 | E51: 2290
C52: Total 1 | E52: 157496.42
C53: Total general | E53: 157496.42

Sheet Detalle1
A1: Detalles para Cobro no realizado. - Apto: 104, Cuotas: 19, ESTATUS CLIENTE: Cliente Atrasado
A3: Apto | B3: Torre | C3: Tipo | D3: Vendedor | E3: Cliente | F3: Reservado | G3: Estatus | H3: Precio de Venta | I3: Enganche | J3: mar-23 | K3: abr-23 | L3: may-23 | M3: jun-23 | N3: jul-23 | O3: ago-23 | P3: sep-23 | Q3: oct-23 | R3: nov-23 | S3: dic-23 | T3: ene-24 | U3: feb-24 | V3: mar-24 | W3: abr-24 | X3: may-24 | Y3: jun-24 | Z3: jul-24 | AA3: ago-24 | AB3: sep-24 | AC3: oct-24 | AD3: nov-24 | AE3: dic-24 | AF3: ene-25 | AG3: feb-25 | AH3: mar-25 | AI3: abr-25 | AJ3: may-25 | AK3: jun-25 | AL3: jul-25 | AM3: ago-25 | AN3: TOTAL COBROS Y RESERVAS | AO3: % Cobro | AP3: SALDO PENDIENTE ENGANCHE | AQ3: % Pendiente | AR3: Monto a Financiar por Banco | AS3: % a Financiar | AT3: Proyección de Cobros (S/ Modelo Financiero) | AU3: Status inmueble | AV3: ESTATUS CLIENTE | AW3: Cuotas Pactadas | AX3: Cuota de Enganche | AY3: Total cuotas pactadas | AZ3: Monto de Reserva Pactado | BA3: Monto de Cuota Pactada | BB3: Cuotas Pagadas | BC3: Cantidad de cuotas que deben estar pagadas por el cliente | BD3: Monto que debe estar cancelado a la fecha | BE3: Monto pagado de cuotas a la fecha | BF3: Enganche + Cuotas Extraordinarias Pagadas | BG3: Diferencia | BH3: Cobro adicional a lo pactado | BI3: Cobro no realizado según lo pactado | BJ3: Cuotas | BK3: Caso Especial / F&F | BL3: Observaciones
A4: 104 | B4: A | C4: B | D4: Abigail Garcia | E4: Astrid Marleny Pineda Gonzalez | F4: 45258 | G4: 4.Plan de pagos | H4: 494900 | I4: 23900 | J4: 0 | K4: 0 | L4: 0 | M4: 0 | N4: 0 | O4: 0 | P4: 0 | Q4: 0 | R4: 0 | S4: 0 | T4: 0 | U4: 0 | V4: 0 | W4: 0 | X4: 0 | Y4: 0 | Z4: 0 | AA4: 0 | AB4: 0 | AC4: 0 | AD4: 300 | AE4: 500 | AF4: 0 | AG4: 0 | AH4: 1000 | AJ4: 500 | AL4: 500 | AN4: 2800 | AO4: 0.11715481 | AP4: -21100 | AQ4: -0.88284519 | AR4: 492100 | AS4: 0.99434229 | AT4: 23900 | AU4: Vendido | AV4: Cliente Atrasado | AW4: 13 | AX4: 1 | AY4: 14 | AZ4: 300 | BA4: 1815.38 | BB4: 0 | BC4: 20 | BD4: 36607.6 | BE4: 2300 | BF4: 0 | BG4: 500 | BH4: 0 | BI4: 33807.6 | BJ4: 19

Sheet ALERTA BEN
F2: RESUMEN
C3: PROYECTO: | D3: BENESTARE
C4: ESTATUS CLIENTE | D4: Cliente Atrasado
C6: Cuotas | D6: Apto | E6: Cobro no realizado.
C7: 0 | D7: 108 | E7: 0
D8: 305 | E8: 0
D9: 403 | E9: 0
D10: 502 | E10: 0
D11: 211 | E11: 0
D12: 412 | E12: 500
D13: 609 | E13: 0
C14: Total 0 | E14: 500
C15: 1 | D15: 105 | E15: 1769.38
D16: 106 | E16: 2228.57
D17: 109 | E17: 1874.5
D18: 205 | E18: 28.77
D19: 213 | E19: 750
D20: 304 | E20: 1426.63
D21: 306 | E21: 34842
D22: 308 | E22: 750
D23: 311 | E23: 84.25
D24: 312 | E24: 1272.22
D25: 401 | E25: 2333.33
D26: 405 | E26: 1800
D27: 407 | E27: 451.01
... D34: 111 | E34: 750
C35: Total 1 | E35: 57373.07
C36: 2 | D36: 301 | E36: 2986.14
D37: 302 | E37: 2800
D38: 305 | E38: 2125
D39: 306 | E39: 44800
D40: 309 | E40: 2800
D41: 504 | E41: 2800
D42: 606 | E42: 1184.21
D43: 610 | E43: 1045.9
D44: (en blanco) | E44: 1500
C45: Total 2 | E45: 62041.25
C46: 3 | D46: 102 | E46: 3733.32
D47: 203 | E47: 3970.59
D48: 207 | E48: 5623.5
...

Sheet ALERTA BLT
F2: RESUMEN
C3: PROYECTO: | D3: Bosque Las Tapias
C4: Status Cliente | D4: Cliente Atrasado
C6: Cuotas | D6: Apto | E6: Cobro no realizado.
C7: 0
D8: 802 | E8: 0
D9: 806 | E9: 0
D10: 908 | E10: 0
D11: 1001 | E11: 0
C12: 2
D13: 904 | E13: 3111.12
D14: 905 | E14: 3055.56
C15: Total general | E15: 6166.68

Sheet SANTA ELISA
B1: 1 | C1: =+B1+1 -> 2 | D1: =+C1+1 -> 3 | E1: =+D1+1 -> 4 | F1: =+E1+1 -> 5 | G1: =+F1+1 -> 6 | H1: =+G1+1 -> 7 | I1: =+H1+1 -> 8 | J1: =+I1+1 -> 9 | ... AS1: =+AR1+1 -> 44
B2: INVERSIONES INMOBILIARIAS SANTA ELISA, S.A.
B3: REPORTE DE RESERVAS | H3: PROMESA FIRMADO POR CLIENTE ( A )
B4: Apto | C4: Vendedor | D4: Cliente | E4: Reservado | F4: Tipo | G4: Cotizador | H4: Precio de Venta | I4: Diferencia Cotizador vs PV | J4: Enganche | K4: Estatus | L4: 44742 | M4: 44773 | N4: 44804 | O4: 44834 | P4: 44865 | Q4: 44895 | R4: 44926 | S4: 44957 | T4: 44985 | U4: 45016 | V4: 45046 | W4: 45077 | X4: 45107 | Y4: 45138 | Z4: 45169 | AA4: 45199 | AB4: 45230 | AC4: 45260 | AD4: 45291 | AE4: 45322 | AF4: 45351 | AG4: 45382 | AH4: 45412 | AI4: 45443 | AJ4: 45473 | AK4: 45504 | AL4: 45535 | AM4: 45565 | AN4: 45596 | AO4: 45626 | AP4: 45657 | AQ4: 45688 | AR4: 45716 | AS4: 45747 | AT4: 45777 | AU4: 45808 | AV4: 45838 | AW4: 45869 | AX4: TOTAL COBROS Y RESERVAS | AY4: % Cobro | AZ4: SALDO PENDIENTE ENGANCHE | BA4: % Pendiente | BB4: Monto a Financiar por Banco | BC4: % a Financiar | BD4: Proyección de Cobros (S/ Modelo Financiero) | BE4: Variación modelo Finan. vs cobro real | BF4: Status inmueble | BG4: ESTATUS CLIENTE | BH4: Cuotas Pactadas | BI4: Cuotas Pagadas | BJ4: Cuotas Atrasadas
B5: 101 | C5: Noemi M. | D5: Thelma Suyapa Aguilera Sanchez de Roca | E5: 44797 | F5: B1 | G5: 806000 | H5: 806000 | I5: =+G5-H5 -> 0 | J5: 80600 | K5: 4.PLAN DE PAGOS | L5: 0 | M5: 0 | N5: 5000 | O5: 3285 | P5: 3285 | Q5: 3285 | R5: 3285 | S5: 3285 | T5: 3285 | U5: 3285 | V5: 3285 | W5: 3285 | X5: 3285 | Y5: 3285 | Z5: 3285 | AA5: 3285 | AB5: 3285 | AC5: 3285 | AD5: 3285 | AE5: 3285 | AF5: 3285 | AG5: 3285 | AH5: 3285 | AI5: 3285 | AJ5: 3285 | AK5: 3330 | AL5: 0 | AM5: 0 | AN5: 0 | AO5: 0 | AP5: 0 | AQ5: 0 | AR5: 0 | AS5: 0 | AT5: 0 | AX5: =SUM(L5:AV5) -> 80600 | AY5: =IFERROR((+AX5/BD5),0) -> 1 | AZ5: =+AX5-BD5 -> 0 | BA5: =IFERROR((+AZ5/BD5),0) -> 0 | BB5: =+H5-AX5 -> 725400 | BC5: =+BB5/H5 -> 0.9 | BD5: =IF(BF5="Vendido",J5*1,IF(BF5="Disponible",J5*0,IF(BF5="Enganche Completado",J5*1,IF(BF5="Superávit de Enganche",J5*1,0)))) -> 80600 | BE5: =IF(D5=0,J5*0,BD5-AX5) -> 0 | BF5: =IF(D5=0,"Apartamento Disponible",IF(D5>1,"Vendido",0)) -> Vendido | BG5: =IF(AND(BF5="Vendido",E5>=0,AZ5=0),"Enganche Completado",IF(AND(BF5="Vendido",E5>=0,AZ5>0),"Superávit de Enganche",IF(AND(BF5="Apartamento Disponible",E5=0,AZ5=0),"Disponible","Cliente Atrasado"))) -> Enganche Completado | BI5: =COUNTIF(L5:AT5,">0.01") -> 24 | BJ5: =IF(AND(BG5="Cliente Atrasado",COUNTIF(L5:AT5,"<0.01")),DATEDIF(E5,AT$4+1,"m"),0) -> 0
B6: 102 | C6: Noemi M. | D6: Cristina Estefanía Villagrán Marroquin | E6: 44934 | F6: B3 | G6: 814000 | H6: 814000 | I6: =+G6-H6 -> 0 | J6: 81400 | K6: 4.PLAN DE PAGOS | L6: 0 | M6: 0 | N6: 0 | O6: 0 | P6: 0 | Q6: 0 | R6: 0 | S6: 5000 | T6: 8480 | U6: 0 | V6: 8480 | W6: 0 | X6: 4240 | Y6: 8480 | Z6: 0 | AA6: 4240 | AB6: 8480 | AC6: 0 | AD6: 8480 | AE6: 4240 | AF6: 0 | AG6: 4240 | AH6: 8480 | AI6: 4240 | AJ6: 0 | AK6: 4320 | AL6: 500 | AM6: 0 | AN6: 0 | AO6: 0 | AP6: 0 | AQ6: 0 | AR6: 0 | AS6: 0 | AT6: 79769.78 | AX6: =SUM(L6:AV6) -> 161669.78 | AY6: =IFERROR((+AX6/BD6),0) -> 1.9861152 | AZ6: =+AX6-BD6 -> 80269.78 | BA6: =IFERROR((+AZ6/BD6),0) -> 0.98611523 | BB6: =+H6-AX6 -> 652330.22 | BC6: =+BB6/H6 -> 0.80138848 | BD6: =IF(BF6="Vendido",J6*1,IF(BF6="Disponible",J6*0,IF(BF6="Enganche Completado",J6*1,IF(BF6="Superávit de Enganche",J6*1,0)))) -> 81400 | BE6: =IF(D6=0,J6*0,BD6-AX6) -> -80269.78 | BF6: =IF(D6=0,"Apartamento Disponible",IF(D6>1,"Vendido",0)) -> Vendido | BG6: =IF(AND(BF6="Vendido",E6>=0,AZ6=0),"Enganche Completado",IF(AND(BF6="Vendido",E6>=0,AZ6>0),"Superávit de Enganche",IF(AND(BF6="Apartamento Disponible",E6=0,AZ6=0),"Disponible","Cliente Atrasado"))) -> Superávit de Enganche | BI6: =COUNTIF(L6:AT6,">0.01") -> 15 | BJ6: =IF(AND(BG6="Cliente Atrasado",COUNTIF(L6:AT6,"<0.01")),DATEDIF(E6,AT$4+1,"m"),0) -> 0
B7: 103 | C7: Paula H. | D7: Chelsy Amarilis Orellana De León | E7: 44895 | F7: A4 | G7: 1265000 | H7: 1265000 | I7: =+G7-H7 -> 0 | J7: 63300 | K7: 4.PLAN DE PAGOS | L7: 0 | M7: 0 | N7: 0 | O7: 0 | P7: 0 | Q7: 0 | R7: 0 | S7: 0 | T7: 0 | U7: 0 | V7: 0 | W7: 0 | X7: 0 | Y7: 0 | Z7: 0 | AA7: 0 | AB7: 0 | AC7: 0 | AD7: 0 | AE7: 0 | AF7: 0 | AG7: 0 | AH7: 0 | AI7: 0 | AJ7: 0 | AK7: 0 | AL7: 0 | AM7: 5000 | AN7: =5000 -> 5000 | AO7: 5000 | AP7: 5000 | AQ7: =1650+20000 -> 21650 | AR7: =20000+1650 -> 21650 | AS7: 0 | AX7: =SUM(L7:AV7) -> 63300 | AY7: =IFERROR((+AX7/BD7),0) -> 1 | AZ7: =+AX7-BD7 -> 0 | BA7: =IFERROR((+AZ7/BD7),0) -> 0 | BB7: =+H7-AX7 -> 1201700 | BC7: =+BB7/H7 -> 0.94996047 | BD7: =IF(BF7="Vendido",J7*1,IF(BF7="Disponible",J7*0,IF(BF7="Enganche Completado",J7*1,IF(BF7="Superávit de Enganche",J7*1,0)))) -> 63300 | BE7: =IF(D7=0,J7*0,BD7-AX7) -> 0 | BF7: =IF(D7=0,"Apartamento Disponible",IF(D7>1,"Vendido",0)) -> Vendido | BG7: =IF(AND(BF7="Vendido",E7>=0,AZ7=0),"Enganche Completado",IF(AND(BF7="Vendido",E7>=0,AZ7>0),"Superávit de Enganche",IF(AND(BF7="Apartamento Disponible",E7=0,AZ7=0),"Disponible","Cliente Atrasado"))) -> Enganche Completado | BI7: =COUNTIF(L7:AT7,">0.01") -> 6 | BJ7: =IF(AND(BG7="Cliente Atrasado",COUNTIF(L7:AT7,"<0.01")),DATEDIF(E7,AT$4+1,"m"),0) -> 0
B8: 104 | C8: Eder Daniel V. | D8: Ada Marcela Moscoso Lopez / Mostello | E8: 45614 | F8: A2 | G8: 1100200 | H8: 1100200 | I8: =+G8-H8 -> 0 | J8: 55100 | K8: 4.PLAN DE PAGOS | L8: 0 | M8: 0 | N8: 0 | O8: 0 | P8: 0 | Q8: 0 | R8: 0 | S8: 0 | T8: 0 | U8: 0 | V8: 0 | W8: 0 | X8: 0 | Y8: 0 | AA8: 0 | AB8: 0 | AC8: 0 | AD8: 0 | AE8: 0 | AF8: 0 | AG8: 0 | AH8: 0 | AI8: 0 | AJ8: 0 | AK8: 0 | AL8: 0 | AM8: 0 | AN8: 0 | AO8: 5000 | AP8: =90+50010 -> 50100 | AQ8: 0 | AR8: 0 | AS8: 0 | AX8: =SUM(L8:AV8) -> 55100 | AY8: =IFERROR((+AX8/BD8),0) -> 1 | AZ8: =+AX8-BD8 -> 0 | BA8: =IFERROR((+AZ8/BD8),0) -> 0 | BB8: =+H8-AX8 -> 1045100 | BC8: =+BB8/H8 -> 0.9499182 | BD8: =IF(BF8="Vendido",J8*1,IF(BF8="Disponible",J8*0,IF(BF8="Enganche Completado",J8*1,IF(BF8="Superávit de Enganche",J8*1,0)))) -> 55100 | BE8: =IF(D8=0,J8*0,BD8-AX8) -> 0 | BF8: =IF(D8=0,"Apartamento Disponible",IF(D8>1,"Vendido",0)) -> Vendido | BG8: =IF(AND(BF8="Vendido",E8>=0,AZ8=0),"Enganche Completado",IF(AND(BF8="Vendido",E8>=0,AZ8>0),"Superávit de Enganche",IF(AND(BF8="Apartamento Disponible",E8=0,AZ8=0),"Disponible","Cliente Atrasado"))) -> Enganche Completado | BI8: =COUNTIF(L8:AT8,">0.01") -> 2 | BJ8: =IF(AND(BG8="Cliente Atrasado",COUNTIF(L8:AT8,"<0.01")),DATEDIF(E8,AT$4+1,"m"),0) -> 0
B9: 105 | C9: Ricardo O. | D9: Juan Pablo Matheu Morales | E9: 44972 | F9: C1 | G9: 639700 | H9: 639700 | I9: =+G9-H9 -> 0 | J9: 64000 | K9: 4.PLAN DE PAGOS | L9: 0 | M9: 0 | N9: 0 | O9: 0 | P9: 0 | Q9: 0 | R9: 0 | S9: 0 | T9: 5000 | U9: 0 | V9: 5000 | W9: 0 | X9: 0 | Y9: 5000 | Z9: 0 | AA9: 0 | AB9: 0 | AC9: 0 | AD9: 0 | AE9: 0 | AF9: 8000 | AG9: 0 | AH9: 2000 | AI9: 0 | AJ9: 2000 | AK9: 14500 | AL9: 0 | AM9: 2000 | AN9: 0 | AO9: 0 | AP9: 0 | AQ9: 0 | AR9: 0 | AS9: 20500 | AX9: =SUM(L9:AV9) -> 64000 | AY9: =IFERROR((+AX9/BD9),0) -> 1 | AZ9: =+AX9-BD9 -> 0 | BA9: =IFERROR((+AZ9/BD9),0) -> 0 | BB9: =+H9-AX9 -> 575700 | BC9: =+BB9/H9 -> 0.8999531 | BD9: =IF(BF9="Vendido",J9*1,IF(BF9="Disponible",J9*0,IF(BF9="Enganche Completado",J9*1,IF(BF9="Superávit de Enganche",J9*1,0)))) -> 64000 | BE9: =IF(D9=0,J9*0,BD9-AX9) -> 0 | BF9: =IF(D9=0,"Apartamento Disponible",IF(D9>1,"Vendido",0)) -> Vendido | BG9: =IF(AND(BF9="Vendido",E9>=0,AZ9=0),"Enganche Completado",IF(AND(BF9="Vendido",E9>=0,AZ9>0),"Superávit de Enganche",IF(AND(BF9="Apartamento Disponible",E9=0,AZ9=0),"Disponible","Cliente Atrasado"))) -> Enganche Completado | BI9: =COUNTIF(L9:AT9,">0.01") -> 9 | BJ9: =IF(AND(BG9="Cliente Atrasado",COUNTIF(L9:AT9,"<0.01")),DATEDIF(E9,AT$4+1,"m"),0) -> 0
B10: 201 | C10: Paula H. | D10: Hernan Benito Guerra Bardales | E10: 45701 | F10: C2 | G10: 650000 | H10: 650000 | I10: =+G10-H10 -> 0 | J10: 650000 | K10: 2.RESERVADO | L10: 0 | M10: 0 | N10: 0 | O10: 0 | P10: 0 | Q10: 0 | R10: 0 | S10: 0 | T10: 0 | U10: 0 | V10: 0 | W10: 0 | X10: 0 | Y10: 0 | AA10: 0 | AB10: 0 | AC10: 0 | AD10: 0 | AE10: 0 | AF10: 0 | AG10: 0 | AH10: 0 | AI10: 0 | AJ10: 0 | AK10: 0 | AL10: 0 | AM10: 0 | AN10: 0 | AO10: 0 | AP10: 0 | AQ10: 0 | AR10: 5000 | AS10: 0 | AX10: =SUM(L10:AV10) -> 5000 | AY10: =IFERROR((+AX10/BD10),0) -> 0.0076923077 | AZ10: =+AX10-BD10 -> -645000 | BA10: =IFERROR((+AZ10/BD10),0) -> -0.99230769 | BB10: =+H10-AX10 -> 645000 | BC10: =+BB10/H10 -> 0.99230769 | BD10: =IF(BF10="Vendido",J10*1,IF(BF10="Disponible",J10*0,IF(BF10="Enganche Completado",J10*1,IF(BF10="Superávit de Enganche",J10*1,0)))) -> 650000 | BE10: =IF(D10=0,J10*0,BD10-AX10) -> 645000 | BF10: =IF(D10=0,"Apartamento Disponible",IF(D10>1,"Vendido",0)) -> Vendido | BG10: =IF(AND(BF10="Vendido",E10>=0,AZ10=0),"Enganche Completado",IF(AND(BF10="Vendido",E10>=0,AZ10>0),"Superávit de Enganche",IF(AND(BF10="Apartamento Disponible",E10=0,AZ10=0),"Disponible","Cliente Atrasado"))) -> Cliente Atrasado | BI10: =COUNTIF(L10:AT10,">0.01") -> 1 | BJ10: =IF(AND(BG10="Cliente Atrasado",COUNTIF(L10:AT10,"<0.01")),DATEDIF(E10,AT$4+1,"m"),0) -> 2
B11: 202 | C11: Paula H. | D11: Ángel Roberto Sic García/ANGEL EDUARDO SIC MORALES | E11: 45398 | F11: A5 | G11: 805400 | H11: 805400 | I11: =+G11-H11 -> 0 | J11: 100000 | K11: 4.PLAN DE PAGOS | L11: 0 | M11: 0 | N11: 0 | O11: 0 | P11: 0 | Q11: 0 | R11: 0 | S11: 0 | T11: 0 | U11: 0 | V11: 0 | W11: 0 | X11: 0 | Y11: 0 | Z11: 0 | AA11: 0 | AB11: 0 | AC11: 0 | AD11: 0 | AE11: 0 | AF11: 0 | AG11: 0 | AH11: 5000 | AI11: 3500 | AJ11: 3500 | AK11: 3500 | AL11: 3500 | AM11: 3500 | AN11: 3500 | AO11: 74000 | AP11: 0 | AQ11: 0 | AR11: 0 | AS11: 0 | AX11: =SUM(L11:AV11) -> 100000 | AY11: =IFERROR((+AX11/BD11),0) -> 1 | AZ11: =+AX11-BD11 -> 0 | BA11: =IFERROR((+AZ11/BD11),0) -> 0 | BB11: =+H11-AX11 -> 705400 | BC11: =+BB11/H11 -> 0.87583809 | BD11: =IF(BF11="Vendido",J11*1,IF(BF11="Disponible",J11*0,IF(BF11="Enganche Completado",J11*1,IF(BF11="Superávit de Enganche",J11*1,0)))) -> 100000 | BE11: =IF(D11=0,J11*0,BD11-AX11) -> 0 | BF11: =IF(D11=0,"Apartamento Disponible",IF(D11>1,"Vendido",0)) -> Vendido | BG11: =IF(AND(BF11="Vendido",E11>=0,AZ11=0),"Enganche Completado",IF(AND(BF11="Vendido",E11>=0,AZ11>0),"Superávit de Enganche",IF(AND(BF11="Apartamento Disponible",E11=0,AZ11=0),"Disponible","Cliente Atrasado"))) -> Enganche Completado | BI11: =COUNTIF(L11:AT11,">0.01") -> 8 | BJ11: =IF(AND(BG11="Cliente Atrasado",COUNTIF(L11:AT11,"<0.01")),DATEDIF(E11,AT$4+1,"m"),0) -> 0
B12: 203 | C12: Francisco S. | D12: Ana Cristina Velásquez de Gómez | E12: 44740 | F12: A6 | G12: 840000 | H12: 840000 | I12: =+G12-H12 -> 0 | J12: 84000 | K12: 4.PLAN DE PAGOS | L12: 5000 | M12: 3434.78 | N12: 3434.78 | O12: 3434.78 | P12: 3434.78 | Q12: 3434.78 | R12: 3434.78 | S12: 3434.78 | T12: 3434.78 | U12: 3434.78 | V12: 3434.78 | W12: 3434.78 | X12: 3434.78 | Y12: 3434.78 | Z12: 3434.78 | AA12: 3434.78 | AB12: 3434.78 | AC12: 3434.78 | AD12: 3434.78 | AE12: 3434.78 | AF12: 3434.78 | AG12: 3434.78 | AH12: 3434.78 | AI12: 3434.78 | AJ12: 0 | AK12: 0.06 | AL12: 0 | AM12: 0 | AN12: 0 | AO12: 0 | AP12: 0 | AQ12: 0 | AR12: 0 | AS12: 66408.51 | AX12: =SUM(L12:AV12) -> 150408.51 | AY12: =IFERROR((+AX12/BD12),0) -> 1.7905775 | AZ12: =+AX12-BD12 -> 66408.51 | BA12: =IFERROR((+AZ12/BD12),0) -> 0.7905775 | BB12: =+H12-AX12 -> 689591.49 | BC12: =+BB12/H12 -> 0.82094225 | BD12: =IF(BF12="Vendido",J12*1,IF(BF12="Disponible",J12*0,IF(BF12="Enganche Completado",J12*1,IF(BF12="Superávit de Enganche",J12*1,0)))) -> 84000 | BE12: =IF(D12=0,J12*0,BD12-AX12) -> -66408.51 | BF12: =IF(D12=0,"Apartamento Disponible",IF(D12>1,"Vendido",0)) -> Vendido | BG12: =IF(AND(BF12="Vendido",E12>=0,AZ12=0),"Enganche Completado",IF(AND(BF12="Vendido",E12>=0,AZ12>0),"Superávit de Enganche",IF(AND(BF12="Apartamento Disponible",E12=0,AZ12=0),"Disponible","Cliente Atrasado"))) -> Superávit de Enganche | BI12: =COUNTIF(L12:AT12,">0.01") -> 26 | BJ12: =IF(AND(BG12="Cliente Atrasado",COUNTIF(L12:AT12,"<0.01")),DATEDIF(E12,AT$4+1,"m"),0) -> 0
B13: 204 | C13: Paula H. | D13: Alfonso Javier Miranda Ramon | E13: 45376 | F13: B2 | G13: 742700 | H13: 742700 | I13: =+G13-H13 -> 0 | J13: 37100 | K13: 4.PLAN DE PAGOS | L13: 0 | M13: 0 | N13: 0 | O13: 0 | P13: 0 | Q13: 0 | R13: 0 | S13: 0 | T13: 0 | U13: 0 | V13: 0 | W13: 0 | X13: 0 | Y13: 0 | Z13: 0 | AA13: 0 | AB13: 0 | AC13: 0 | AD13: 0 | AE13: 0 | AF13: 0 | AG13: 3000 | AH13: 3000 | AI13: 3000 | AJ13: 3000 | AK13: 0 | AL13: 3000 | AM13: 3000 | AN13: 0 | AO13: 0 | AP13: 3000 | AQ13: 16200 | AR13: 0 | AS13: 259806.91 | AX13: =SUM(L13:AV13) -> 297006.91 | AY13: =IFERROR((+AX13/BD13),0) -> 8.0055771 | AZ13: =+AX13-BD13 -> 259906.91 | BA13: =IFERROR((+AZ13/BD13),0) -> 7.0055771 | BB13: =+H13-AX13 -> 445693.09 | BC13: =+BB13/H13 -> 0.60009841 | BD13: =IF(BF13="Vendido",J13*1,IF(BF13="Disponible",J13*0,IF(BF13="Enganche Completado",J13*1,IF(BF13="Superávit de Enganche",J13*1,0)))) -> 37100 | BE13: =IF(D13=0,J13*0,BD13-AX13) -> -259906.91 | BF13: =IF(D13=0,"Apartamento Disponible",IF(D13>1,"Vendido",0)) -> Vendido | BG13: =IF(AND(BF13="Vendido",E13>=0,AZ13=0),"Enganche Completado",IF(AND(BF13="Vendido",E13>=0,AZ13>0),"Superávit de Enganche",IF(AND(BF13="Apartamento Disponible",E13=0,AZ13=0),"Disponible","Cliente Atrasado"))) -> Superávit de Enganche | BI13: =COUNTIF(L13:AT13,">0.01") -> 9 | BJ13: =IF(AND(BG13="Cliente Atrasado",COUNTIF(L13:AT13,"<0.01")),DATEDIF(E13,AT$4+1,"m"),0) -> 0
B14: 205 | C14: Paula H. | D14: Elfego Adonias Apen Son y Dany Alexis Gómez Ajuchán | E14: 45152 | F14: B2 | G14: 718200 | H14: 733200 | I14: =+G14-H14 -> -15000 | J14: 73320 | K14: 4.PLAN DE PAGOS | L14: 0 | M14: 0 | N14: 0 | O14: 0 | P14: 0 | Q14: 0 | R14: 0 | S14: 0 | T14: 0 | U14: 0 | V14: 0 | W14: 0 | X14: 0 | Y14: 0 | Z14: 6000 | AA14: 6000 | AB14: 6000 | AC14: 6000 | AD14: 6000 | AE14: 8000 | AF14: 8000 | AG14: 7000 | AH14: 6000 | AI14: 5700 | AJ14: 6000 | AK14: 8000 | AL14: 10000 | AM14: 12000 | AN14: 12000 | AO14: 10250 | AP14: 10250 | AQ14: 0 | AR14: 0 | AS14: 164970.28 | AX14: =SUM(L14:AV14) -> 298170.28 | AY14: =IFERROR((+AX14/BD14),0) -> 4.0666978 | AZ14: =+AX14-BD14 -> 224850.28 | BA14: =IFERROR((+AZ14/BD14),0) -> 3.0666978 | BB14: =+H14-AX14 -> 435029.72 | BC14: =+BB14/H14 -> 0.59333022 | BD14: =IF(BF14="Vendido",J14*1,IF(BF14="Disponible",J14*0,IF(BF14="Enganche Completado",J14*1,IF(BF14="Superávit de Enganche",J14*1,0)))) -> 73320 | BE14: =IF(D14=0,J14*0,BD14-AX14) -> -224850.28 | BF14: =IF(D14=0,"Apartamento Disponible",IF(D14>1,"Vendido",0)) -> Vendido | BG14: =IF(AND(BF14="Vendido",E14>=0,AZ14=0),"Enganche Completado",IF(AND(BF14="Vendido",E14>=0,AZ14>0),"Superávit de Enganche",IF(AND(BF14="Apartamento Disponible",E14=0,AZ14=0),"Disponible","Cliente Atrasado"))) -> Superávit de Enganche | BI14: =COUNTIF(L14:AT14,">0.01") -> 18 | BJ14: =IF(AND(BG14="Cliente Atrasado",COUNTIF(L14:AT14,"<0.01")),DATEDIF(E14,AT$4+1,"m"),0) -> 0
B15: 206 | C15: Efren Sanchez | D15: José Pablo Arana López | E15: 45636 | F15: A3 | G15: 948800 | H15: =680566.51+268233.49 -> 948800 | I15: =+G15-H15 -> 0 | J15: 47500 | K15: 2.RESERVADO | L15: 0 | M15: 0 | N15: 0 | O15: 0 | P15: 0 | Q15: 0 | R15: 0 | S15: 0 | T15: 0 | U15: 0 | V15: 0 | W15: 0 | X15: 0 | Y15: 0 | AA15: 0 | AB15: 0 | AC15: 0 | AD15: 0 | AE15: 0 | AF15: 0 | AG15: 0 | AH15: 0 | AI15: 0 | AJ15: 0 | AK15: 0 | AL15: 0 | AM15: 0 | AN15: 0 | AO15: 0 | AP15: =2500+2500 -> 5000 | AQ15: 0 | AR15: 0 | AS15: 20000 | AX15: =SUM(L15:AV15) -> 25000 | AY15: =IFERROR((+AX15/BD15),0) -> 0.52631579 | AZ15: =+AX15-BD15 -> -22500 | BA15: =IFERROR((+AZ15/BD15),0) -> -0.47368421 | BB15: =+H15-AX15 -> 923800 | BC15: =+BB15/H15 -> 0.97365093 | BD15: =IF(BF15="Vendido",J15*1,IF(BF15="Disponible",J15*0,IF(BF15="Enganche Completado",J15*1,IF(BF15="Superávit de Enganche",J15*1,0)))) -> 47500 | BE15: =IF(D15=0,J15*0,BD15-AX15) -> 22500 | BF15: =IF(D15=0,"Apartamento Disponible",IF(D15>1,"Vendido",0)) -> Vendido | BG15: =IF(AND(BF15="Vendido",E15>=0,AZ15=0),"Enganche Completado",IF(AND(BF15="Vendido",E15>=0,AZ15>0),"Superávit de Enganche",IF(AND(BF15="Apartamento Disponible",E15=0,AZ15=0),"Disponible","Cliente Atrasado"))) -> Cliente Atrasado | BI15: =COUNTIF(L15:AT15,">0.01") -> 2 | BJ15: 3
B16: 207 | C16: Paula H. | D16: Edwin Oswaldo Saenz Marroquin y Leslie Gabriela Senz | E16: 45347 | F16: A1 | G16: 769700 | H16: 769700 | I16: =+G16-H16 -> 0 | J16: 38500 | K16: 4.PLAN DE PAGOS | L16: 0 | M16: 0 | N16: 0 | O16: 0 | P16: 0 | Q16: 0 | R16: 0 | S16: 0 | T16: 0 | U16: 0 | V16: 0 | W16: 0 | X16: 0 | Y16: 0 | Z16: 0 | AA16: 0 | AB16: 0 | AC16: 0 | AD16: 0 | AE16: 0 | AF16: 5000 | AG16: 3700 | AH16: 7420.56 | AI16: 3700 | AJ16: 3700 | AK16: 3700 | AL16: 3700 | AM16: 3700 | AN16: 3700 | AO16: 3700 | AP16: =10000+10000+8500 -> 28500 | AQ16: 10000 | AR16: 220489.16 | AS16: 0 | AX16: =SUM(L16:AV16) -> 301009.72 | AY16: =IFERROR((+AX16/BD16),0) -> 7.8184343 | AZ16: =+AX16-BD16 -> 262509.72 | BA16: =IFERROR((+AZ16/BD16),0) -> 6.8184343 | BB16: =+H16-AX16 -> 468690.28 | BC16: =+BB16/H16 -> 0.60892592 | BD16: =IF(BF16="Vendido",J16*1,IF(BF16="Disponible",J16*0,IF(BF16="Enganche Completado",J16*1,IF(BF16="Superávit de Enganche",J16*1,0)))) -> 38500 | BE16: =IF(D16=0,J16*0,BD16-AX16) -> -262509.72 | BF16: =IF(D16=0,"Apartamento Disponible",IF(D16>1,"Vendido",0)) -> Vendido | BG16: =IF(AND(BF16="Vendido",E16>=0,AZ16=0),"Enganche Completado",IF(AND(BF16="Vendido",E16>=0,AZ16>0),"Superávit de Enganche",IF(AND(BF16="Apartamento Disponible",E16=0,AZ16=0),"Disponible","Cliente Atrasado"))) -> Superávit de Enganche | BI16: =COUNTIF(L16:AT16,">0.01") -> 13 | BJ16: =IF(AND(BG16="Cliente Atrasado",COUNTIF(L16:AT16,"<0.01")),DATEDIF(E16,AT$4+1,"m"),0) -> 0
B17: 208 | F17: C2 | G17: 650000 | H17: 650000 | I17: =+G17-H17 -> 0 | J17: 65000 | K17: 1.DISPONIBLE | L17: 0 | M17: 0 | N17: 0 | O17: 0 | P17: 0 | Q17: 0 | R17: 0 | S17: 0 | T17: 0 | U17: 0 | V17: 0 | W17: 0 | X17: 0 | Y17: 0 | Z17: 0 | AA17: 0 | AB17: 0 | AC17: 0 | AD17: 0 | AE17: 0 | AF17: 0 | AG17: 0 | AH17: 0 | AI17: 0 | AJ17: 0 | AK17: 0 | AL17: 0 | AM17: 0 | AN17: 0 | AO17: 0 | AP17: 0 | AQ17: 0 | AR17: 0 | AS17: 0 | AX17: =SUM(L17:AV17) -> 0 | AY17: =IFERROR((+AX17/BD17),0) -> 0 | AZ17: =+AX17-BD17 -> 0 | BA17: =IFERROR((+AZ17/BD17),0) -> 0 | BB17: =+H17-AX17 -> 650000 | BC17: =+BB17/H17 -> 1 | BD17: =IF(BF17="Vendido",J17*1,IF(BF17="Disponible",J17*0,IF(BF17="Enganche Completado",J17*1,IF(BF17="Superávit de Enganche",J17*1,0)))) -> 0 | BE17: =IF(D17=0,J17*0,BD17-AX17) -> 0 | BF17: =IF(D17=0,"Apartamento Disponible",IF(D17>1,"Vendido",0)) -> Apartamento Disponible | BG17: =IF(AND(BF17="Vendido",E17>=0,AZ17=0),"Enganche Completado",IF(AND(BF17="Vendido",E17>=0,AZ17>0),"Superávit de Enganche",IF(AND(BF17="Apartamento Disponible",E17=0,AZ17=0),"Disponible","Cliente Atrasado"))) -> Disponible | BI17: =COUNTIF(L17:AT17,">0.01") -> 0 | BJ17: =IF(AND(BG17="Cliente Atrasado",COUNTIF(L17:AT17,"<0.01")),DATEDIF(E17,AT$4+1,"m"),0) -> 0
B18: 301 | C18: Noemi M. | D18: Héctor Enrique Zacarias Illescas | E18: 44996 | F18: C2 | G18: 572700 | H18: 572700 | I18: =+G18-H18 -> 0 | J18: 58000 | K18: 4.PLAN DE PAGOS | L18: 0 | M18: 0 | N18: 0 | O18: 0 | P18: 0 | Q18: 0 | R18: 0 | S18: 0 | T18: 0 | U18: 7500 | V18: 10000 | W18: 20000 | X18: 0 | Y18: 10000 | Z18: 20000 | AA18: 12500 | AB18: 0 | AC18: 0 | AD18: 0 | AE18: 0 | AF18: 10000 | AG18: 0 | AH18: 30000 | AI18: 5000 | AJ18: 15000 | AK18: 0 | AL18: 0 | AM18: 20000 | AN18: 40000 | AO18: 0 | AP18: 0 | AQ18: 0 | AR18: 5000 | AS18: 0 | AT18: 58222.13 | AX18: =SUM(L18:AV18) -> 263222.13 | AY18: =IFERROR((+AX18/BD18),0) -> 4.5383126 | AZ18: =+AX18-BD18 -> 205222.13 | BA18: =IFERROR((+AZ18/BD18),0) -> 3.5383126 | BB18: =+H18-AX18 -> 309477.87 | BC18: =+BB18/H18 -> 0.54038392 | BD18: =IF(BF18="Vendido",J18*1,IF(BF18="Disponible",J18*0,IF(BF18="Enganche Completado",J18*1,IF(BF18="Superávit de Enganche",J18*1,0)))) -> 58000 | BE18: =IF(D18=0,J18*0,BD18-AX18) -> -205222.13 | BF18: =IF(D18=0,"Apartamento Disponible",IF(D18>1,"Vendido",0)) -> Vendido | BG18: =IF(AND(BF18="Vendido",E18>=0,AZ18=0),"Enganche Completado",IF(AND(BF18="Vendido",E18>=0,AZ18>0),"Superávit de Enganche",IF(AND(BF18="Apartamento Disponible",E18=0,AZ18=0),"Disponible","Cliente Atrasado"))) -> Superávit de Enganche | BI18: =COUNTIF(L18:AT18,">0.01") -> 14 | BJ18: =IF(AND(BG18="Cliente Atrasado",COUNTIF(L18:AT18,"<0.01")),DATEDIF(E18,AT$4+1,"m"),0) -> 0
B19: 302 | C19: Eder Veliz | D19: Guilmar Renato Najarro Díaz | E19: 45763 | F19: A1 | G19: 698000 | H19: 815000 | I19: =+G19-H19 -> -117000 | J19: 200000 | K19: 2. RESERVADO | L19: 0 | M19: 0 | N19: 0 | O19: 0 | P19: 0 | Q19: 0 | R19: 0 | S19: 0 | T19: 0 | U19: 0 | V19: 0 | W19: 0 | X19: 0 | Y19: 0 | Z19: 0 | AA19: 0 | AB19: 0 | AC19: 0 | AD19: 0 | AE19: 0 | AF19: 0 | AG19: 0 | AH19: 0 | AI19: 0 | AJ19: 0 | AK19: 0 | AL19: 0 | AM19: 0 | AN19: 0 | AO19: 0 | AP19: 0 | AQ19: 0 | AR19: 0 | AS19: 0 | AT19: 0 | AU19: 97500 | AX19: =SUM(L19:AV19) -> 97500 | AY19: =IFERROR((+AX19/BD19),0) -> 0.4875 | AZ19: =+AX19-BD19 -> -102500 | BA19: =IFERROR((+AZ19/BD19),0) -> -0.5125 | BB19: =+H19-AX19 -> 717500 | BC19: =+BB19/H19 -> 0.8803681 | BD19: =IF(BF19="Vendido",J19*1,IF(BF19="Disponible",J19*0,IF(BF19="Enganche Completado",J19*1,IF(BF19="Superávit de Enganche",J19*1,0)))) -> 200000 | BE19: =IF(D19=0,J19*0,BD19-AX19) -> 102500 | BF19: =IF(D19=0,"Apartamento Disponible",IF(D19>1,"Vendido",0)) -> Vendido | BG19: =IF(AND(BF19="Vendido",E19>=0,AZ19=0),"Enganche Completado",IF(AND(BF19="Vendido",E19>=0,AZ19>0),"Superávit de Enganche",IF(AND(BF19="Apartamento Disponible",E19=0,AZ19=0),"Disponible","Cliente Atrasado"))) -> Cliente Atrasado | BI19: =COUNTIF(L19:AT19,">0.01") -> 0 | BJ19: 20 | BK19: Dep. Reserva | BM19: Sin promesa firmada
B20: 303 | C20: Paula H. | D20: Sofia Maricela Ozaeta Góngora de Vásquez y Samuel Alejandro Vásquez Maldonado | E20: 45572 | F20: A3 | G20: 960966 | H20: 960966 | I20: =+G20-H20 -> 0 | J20: 48066 | K20: 4.PLAN DE PAGOS | L20: 0 | M20: 0 | N20: 0 | O20: 0 | P20: 0 | Q20: 0 | R20: 0 | S20: 0 | T20: 0 | U20: 0 | V20: 0 | W20: 0 | X20: 0 | Y20: 0 | AA20: 0 | AB20: 0 | AC20: 0 | AD20: 0 | AE20: 0 | AF20: 0 | AG20: 0 | AH20: 0 | AI20: 0 | AJ20: 0 | AK20: 0 | AL20: 0 | AM20: 0 | AN20: 48066 | AO20: 0 | AP20: 0 | AQ20: 0 | AR20: 0 | AS20: 366021.32 | AX20: =SUM(L20:AV20) -> 414087.32 | AY20: =IFERROR((+AX20/BD20),0) -> 8.6149736 | AZ20: =+AX20-BD20 -> 366021.32 | BA20: =IFERROR((+AZ20/BD20),0) -> 7.6149736 | BB20: =+H20-AX20 -> 546878.68 | BC20: =+BB20/H20 -> 0.56909264 | BD20: =IF(BF20="Vendido",J20*1,IF(BF20="Disponible",J20*0,IF(BF20="Enganche Completado",J20*1,IF(BF20="Superávit de Enganche",J20*1,0)))) -> 48066 | BE20: =IF(D20=0,J20*0,BD20-AX20) -> -366021.32 | BF20: =IF(D20=0,"Apartamento Disponible",IF(D20>1,"Vendido",0)) -> Vendido | BG20: =IF(AND(BF20="Vendido",E20>=0,AZ20=0),"Enganche Completado",IF(AND(BF20="Vendido",E20>=0,AZ20>0),"Superávit de Enganche",IF(AND(BF20="Apartamento Disponible",E20=0,AZ20=0),"Disponible","Cliente Atrasado"))) -> Superávit de Enganche | BI20: =COUNTIF(L20:AT20,">0.01") -> 2 | BJ20: =IF(AND(BG20="Cliente Atrasado",COUNTIF(L20:AT20,"<0.01")),DATEDIF(E20,AT$4+1,"m"),0) -> 0
B21: 304 | C21: Ricardo O. | D21: Luis Alfonso Ramirez Rivas | E21: 44963 | F21: B2 | G21: 655000 | H21: 655000 | I21: =+G21-H21 -> 0 | J21: 130000 | K21: 4.PLAN DE PAGOS | L21: 0 | M21: 0 | N21: 0 | O21: 0 | P21: 0 | Q21: 0 | R21: 0 | S21: 0 | T21: 70500 | U21: 3500 | V21: 3500 | W21: 3500 | X21: 3500 | Y21: 3500 | Z21: 3500 | AA21: 3500 | AB21: 3500 | AC21: 3500 | AD21: 3500 | AE21: 3500 | AF21: 3500 | AG21: 3500 | AH21: 3500 | AI21: 3500 | AJ21: 3500 | AK21: 3500 | AL21: 3500 | AM21: 0 | AN21: 0 | AO21: 0 | AP21: 0 | AQ21: 0 | AR21: 0 | AS21: 64894.55 | AX21: =SUM(L21:AV21) -> 198394.55 | AY21: =IFERROR((+AX21/BD21),0) -> 1.5261119 | AZ21: =+AX21-BD21 -> 68394.55 | BA21: =IFERROR((+AZ21/BD21),0) -> 0.52611192 | BB21: =+H21-AX21 -> 456605.45 | BC21: =+BB21/H21 -> 0.69710756 | BD21: =IF(BF21="Vendido",J21*1,IF(BF21="Disponible",J21*0,IF(BF21="Enganche Completado",J21*1,IF(BF21="Superávit de Enganche",J21*1,0)))) -> 130000 | BE21: =IF(D21=0,J21*0,BD21-AX21) -> -68394.55 | BF21: =IF(D21=0,"Apartamento Disponible",IF(D21>1,"Vendido",0)) -> Vendido | BG21: =IF(AND(BF21="Vendido",E21>=0,AZ21=0),"Enganche Completado",IF(AND(BF21="Vendido",E21>=0,AZ21>0),"Superávit de Enganche",IF(AND(BF21="Apartamento Disponible",E21=0,AZ21=0),"Disponible","Cliente Atrasado"))) -> Superávit de Enganche | BI21: =COUNTIF(L21:AT21,">0.01") -> 20 | BJ21: =IF(AND(BG21="Cliente Atrasado",COUNTIF(L21:AT21,"<0.01")),DATEDIF(E21,AT$4+1,"m"),0) -> 0
B22: 305 | C22: Ricardo O. | D22: Carol Analí Ovalle Valladares | E22: 44957 | F22: B2 | G22: 655000 | H22: 655000 | I22: =+G22-H22 -> 0 | J22: 100000 | K22: 4.PLAN DE PAGOS | L22: 0 | M22: 0 | N22: 0 | O22: 0 | P22: 0 | Q22: 0 | R22: 0 | S22: 5000 | T22: 5275 | U22: 5275 | V22: 5275 | W22: 5275 | X22: 5275 | Y22: 5275 | Z22: 5275 | AA22: 5275 | AB22: 5275 | AC22: 5275 | AD22: 5275 | AE22: 5275 | AF22: 5275 | AG22: 5275 | AH22: 5275 | AI22: 5275 | AJ22: 5275 | AK22: 5275 | AL22: 5275 | AM22: 105275 | AN22: 0 | AO22: 0 | AP22: 0 | AQ22: 0 | AR22: 0 | AS22: 9470.28 | AX22: =SUM(L22:AV22) -> 219970.28 | AY22: =IFERROR((+AX22/BD22),0) -> 2.1997028 | AZ22: =+AX22-BD22 -> 119970.28 | BA22: =IFERROR((+AZ22/BD22),0) -> 1.1997028 | BB22: =+H22-AX22 -> 435029.72 | BC22: =+BB22/H22 -> 0.66416751 | BD22: =IF(BF22="Vendido",J22*1,IF(BF22="Disponible",J22*0,IF(BF22="Enganche Completado",J22*1,IF(BF22="Superávit de Enganche",J22*1,0)))) -> 100000 | BE22: =IF(D22=0,J22*0,BD22-AX22) -> -119970.28 | BF22: =IF(D22=0,"Apartamento Disponible",IF(D22>1,"Vendido",0)) -> Vendido | BG22: =IF(AND(BF22="Vendido",E22>=0,AZ22=0),"Enganche Completado",IF(AND(BF22="Vendido",E22>=0,AZ22>0),"Superávit de Enganche",IF(AND(BF22="Apartamento Disponible",E22=0,AZ22=0),"Disponible","Cliente Atrasado"))) -> Superávit de Enganche | BI22: =COUNTIF(L22:AT22,">0.01") -> 22 | BJ22: =IF(AND(BG22="Cliente Atrasado",COUNTIF(L22:AT22,"<0.01")),DATEDIF(E22,AT$4+1,"m"),0) -> 0
B23: 306 | C23: Antonio R | D23: Lucy Rivas y Jefferson Daniel Mejía Jocol | E23: 45632 | F23: A3 | G23: 948800 | H23: 948800 | I23: =+G23-H23 -> 0 | J23: 47500 | K23: 4.PLAN DE PAGOS | L23: 0 | M23: 0 | N23: 0 | O23: 0 | P23: 0 | Q23: 0 | R23: 0 | S23: 0 | T23: 0 | U23: 0 | V23: 0 | W23: 0 | X23: 0 | Y23: 0 | Z23: 0 | AA23: 0 | AB23: 0 | AC23: 0 | AD23: 0 | AE23: 0 | AF23: 0 | AG23: 0 | AH23: 0 | AI23: 0 | AJ23: 0 | AK23: 0 | AL23: 0 | AM23: 0 | AN23: 0 | AO23: 0 | AP23: 5000 | AQ23: 28100 | AR23: 0 | AS23: 0 | AT23: 0 | AX23: =SUM(L23:AV23) -> 33100 | AY23: =IFERROR((+AX23/BD23),0) -> 0.69684211 | AZ23: =+AX23-BD23 -> -14400 | BA23: =IFERROR((+AZ23/BD23),0) -> -0.30315789 | BB23: =+H23-AX23 -> 915700 | BC23: =+BB23/H23 -> 0.96511383 | BD23: =IF(BF23="Vendido",J23*1,IF(BF23="Disponible",J23*0,IF(BF23="Enganche Completado",J23*1,IF(BF23="Superávit de Enganche",J23*1,0)))) -> 47500 | BE23: =IF(D23=0,J23*0,BD23-AX23) -> 14400 | BF23: =IF(D23=0,"Apartamento Disponible",IF(D23>1,"Vendido",0)) -> Vendido | BG23: =IF(AND(BF23="Vendido",E23>=0,AZ23=0),"Enganche Completado",IF(AND(BF23="Vendido",E23>=0,AZ23>0),"Superávit de Enganche",IF(AND(BF23="Apartamento Disponible",E23=0,AZ23=0),"Disponible","Cliente Atrasado"))) -> Cliente Atrasado | BI23: =COUNTIF(L23:AT23,">0.01") -> 2 | BJ23: 3
B24: 307 | C24: Eder V. | D24: Narda Guisela Guerrero Reyna | E24: 45635 | F24: A1 | G24: 810000 | H24: =581006.4+228993.6 -> 810000 | I24: =+G24-H24 -> 0 | J24: 40500 | K24: 4.PLAN DE PAGOS | L24: 0 | M24: 0 | N24: 0 | O24: 0 | P24: 0 | Q24: 0 | R24: 0 | S24: 0 | T24: 0 | U24: 0 | V24: 0 | W24: 0 | X24: 0 | Y24: 0 | Z24: 0 | AA24: 0 | AB24: 0 | AC24: 0 | AD24: 0 | AE24: 0 | AF24: 0 | AG24: 0 | AH24: 0 | AI24: 0 | AJ24: 0 | AK24: 0 | AL24: 0 | AM24: 0 | AN24: 0 | AO24: 0 | AP24: 5000 | AQ24: 0 | AR24: 0 | AS24: 35500 | AU24: =40500+138100 -> 178600 | AX24: =SUM(L24:AV24) -> 219100 | AY24: =IFERROR((+AX24/BD24),0) -> 5.4098765 | AZ24: =+AX24-BD24 -> 178600 | BA24: =IFERROR((+AZ24/BD24),0) -> 4.4098765 | BB24: =+H24-AX24 -> 590900 | BC24: =+BB24/H24 -> 0.72950617 | BD24: =IF(BF24="Vendido",J24*1,IF(BF24="Disponible",J24*0,IF(BF24="Enganche Completado",J24*1,IF(BF24="Superávit de Enganche",J24*1,0)))) -> 40500 | BE24: =IF(D24=0,J24*0,BD24-AX24) -> -178600 | BF24: =IF(D24=0,"Apartamento Disponible",IF(D24>1,"Vendido",0)) -> Vendido | BG24: =IF(AND(BF24="Vendido",E24>=0,AZ24=0),"Enganche Completado",IF(AND(BF24="Vendido",E24>=0,AZ24>0),"Superávit de Enganche",IF(AND(BF24="Apartamento Disponible",E24=0,AZ24=0),"Disponible","Cliente Atrasado"))) -> Superávit de Enganche | BI24: =COUNTIF(L24:AT24,">0.01") -> 2 | BJ24: =IF(AND(BG24="Cliente Atrasado",COUNTIF(L24:AT24,"<0.01")),DATEDIF(E24,AT$4+1,"m"),0) -> 0
B25: 308 | C25: Paula H. | D25: Rudy Antonio Hernández Ramos | E25: 45653 | F25: C2 | G25: 650000 | H25: 680000 | I25: =+G25-H25 -> -30000 | J25: 34000 | K25: 4.PLAN DE PAGOS | L25: 0 | M25: 0 | N25: 0 | O25: 0 | P25: 0 | Q25: 0 | R25: 0 | S25: 0 | T25: 0 | AG25: 0 | AH25: 0 | AI25: 0 | AJ25: 0 | AK25: 0 | AL25: 0 | AO25: 0 | AP25: 5000 | AQ25: 0 | AR25: 0 | AS25: 60000 | AX25: =SUM(L25:AV25) -> 65000 | AY25: =IFERROR((+AX25/BD25),0) -> 1.9117647 | AZ25: =+AX25-BD25 -> 31000 | BA25: =IFERROR((+AZ25/BD25),0) -> 0.91176471 | BB25: =+H25-AX25 -> 615000 | BC25: =+BB25/H25 -> 0.90441176 | BD25: =IF(BF25="Vendido",J25*1,IF(BF25="Disponible",J25*0,IF(BF25="Enganche Completado",J25*1,IF(BF25="Superávit de Enganche",J25*1,0)))) -> 34000 | BE25: =IF(D25=0,J25*0,BD25-AX25) -> -31000 | BF25: =IF(D25=0,"Apartamento Disponible",IF(D25>1,"Vendido",0)) -> Vendido | BG25: =IF(AND(BF25="Vendido",E25>=0,AZ25=0),"Enganche Completado",IF(AND(BF25="Vendido",E25>=0,AZ25>0),"Superávit de Enganche",IF(AND(BF25="Apartamento Disponible",E25=0,AZ25=0),"Disponible","Cliente Atrasado"))) -> Superávit de Enganche | BI25: =COUNTIF(L25:AT25,">0.01") -> 2 | BJ25: =IF(AND(BG25="Cliente Atrasado",COUNTIF(L25:AT25,"<0.01")),DATEDIF(E25,AT$4+1,"m"),0) -> 0
B26: 401 | C26: Noemi M. | D26: Héctor René Guzmán Morán | E26: 44880 | F26: C2 | G26: 547800 | H26: 547800 | I26: =+G26-H26 -> 0 | J26: 54780 | K26: 4.PLAN DE PAGOS | L26: 0 | M26: 0 | N26: 0 | O26: 0 | P26: 0 | Q26: 5000 | R26: 2480 | S26: 2480 | T26: 2480 | U26: 2480 | V26: 2480 | W26: 2480 | X26: 2480 | Y26: 2480 | Z26: 2480 | AA26: 2480 | AB26: 2480 | AC26: 2480 | AD26: 2480 | AE26: 2480 | AF26: 2480 | AG26: 2480 | AH26: 2480 | AI26: 2480 | AJ26: 2480 | AK26: 2660 | AL26: 0 | AM26: 0 | AN26: 2505 | AO26: 2505 | AP26: 2505 | AQ26: 2505 | AR26: 0 | AS26: 0 | AX26: =SUM(L26:AV26) -> 64800 | AY26: =IFERROR((+AX26/BD26),0) -> 1.1829135 | AZ26: =+AX26-BD26 -> 10020 | BA26: =IFERROR((+AZ26/BD26),0) -> 0.18291347 | BB26: =+H26-AX26 -> 483000 | BC26: =+BB26/H26 -> 0.88170865 | BD26: =IF(BF26="Vendido",J26*1,IF(BF26="Disponible",J26*0,IF(BF26="Enganche Completado",J26*1,IF(BF26="Superávit de Enganche",J26*1,0)))) -> 54780 | BE26: =IF(D26=0,J26*0,BD26-AX26) -> -10020 | BF26: =IF(D26=0,"Apartamento Disponible",IF(D26>1,"Vendido",0)) -> Vendido | BG26: =IF(AND(BF26="Vendido",E26>=0,AZ26=0),"Enganche Completado",IF(AND(BF26="Vendido",E26>=0,AZ26>0),"Superávit de Enganche",IF(AND(BF26="Apartamento Disponible",E26=0,AZ26=0),"Disponible","Cliente Atrasado"))) -> Superávit de Enganche | BI26: =COUNTIF(L26:AT26,">0.01") -> 25 | BJ26: =IF(AND(BG26="Cliente Atrasado",COUNTIF(L26:AT26,"<0.01")),DATEDIF(E26,AT$4+1,"m"),0) -> 0
B27: 402 | C27: Paula H. | D27: Luis Fernando Cifuentes Echeverria | E27: 45125 | F27: A1 | G27: 703900 | H27: 703900 | I27: =+G27-H27 -> 0 | J27: 70390 | K27: 4.PLAN DE PAGOS | L27: 0 | M27: 0 | N27: 0 | O27: 0 | P27: 0 | Q27: 0 | R27: 0 | S27: 0 | T27: 0 | U27: 0 | V27: 0 | W27: 0 | X27: 0 | Y27: 5000 | Z27: 9500 | AA27: 5500 | AB27: 5500 | AC27: 5500 | AD27: 5500 | AE27: 1500 | AF27: 5500 | AG27: 5500 | AH27: 5500 | AI27: 5500 | AJ27: 35500 | AK27: 35500 | AL27: 30000 | AM27: 30000 | AN27: 0 | AO27: 60000 | AP27: 30000 | AR27: 0 | AS27: 0 | AX27: =SUM(L27:AV27) -> 281000 | AY27: =IFERROR((+AX27/BD27),0) -> 3.9920443 | AZ27: =+AX27-BD27 -> 210610 | BA27: =IFERROR((+AZ27/BD27),0) -> 2.9920443 | BB27: =+H27-AX27 -> 422900 | BC27: =+BB27/H27 -> 0.60079557 | BD27: =IF(BF27="Vendido",J27*1,IF(BF27="Disponible",J27*0,IF(BF27="Enganche Completado",J27*1,IF(BF27="Superávit de Enganche",J27*1,0)))) -> 70390 | BE27: =IF(D27=0,J27*0,BD27-AX27) -> -210610 | BF27: =IF(D27=0,"Apartamento Disponible",IF(D27>1,"Vendido",0)) -> Vendido | BG27: =IF(AND(BF27="Vendido",E27>=0,AZ27=0),"Enganche Completado",IF(AND(BF27="Vendido",E27>=0,AZ27>0),"Superávit de Enganche",IF(AND(BF27="Apartamento Disponible",E27=0,AZ27=0),"Disponible","Cliente Atrasado"))) -> Superávit de Enganche | BI27: =COUNTIF(L27:AT27,">0.01") -> 17 | BJ27: =IF(AND(BG27="Cliente Atrasado",COUNTIF(L27:AT27,"<0.01")),DATEDIF(E27,AT$4+1,"m"),0) -> 0
B28: 403 | C28: Paula H. | D28: José Carlos Sanchez Jimenez | E28: 45761 | F28: A3 | G28: 948800 | H28: =691786.39+272655.61 -> 964442 | I28: =+G28-H28 -> -15642 | J28: 48242 | K28: 2. RESERVADO | L28: 0 | M28: 0 | N28: 0 | O28: 0 | P28: 0 | Q28: 0 | R28: 0 | S28: 0 | T28: 0 | U28: 0 | V28: 0 | W28: 0 | X28: 0 | Y28: 0 | Z28: 0 | AA28: 0 | AB28: 0 | AC28: 0 | AD28: 0 | AE28: 0 | AF28: 0 | AG28: 0 | AH28: 0 | AI28: 0 | AJ28: 0 | AK28: 0 | AL28: 0 | AM28: 0 | AN28: 0 | AO28: 0 | AP28: 0 | AQ28: 0 | AR28: 0 | AS28: 0 | AU28: 21621 | AX28: =SUM(L28:AV28) -> 21621 | AY28: =IFERROR((+AX28/BD28),0) -> 0.44817794 | AZ28: =+AX28-BD28 -> -26621 | BA28: =IFERROR((+AZ28/BD28),0) -> -0.55182206 | BB28: =+H28-AX28 -> 942821 | BC28: =+BB28/H28 -> 0.97758186 | BD28: =IF(BF28="Vendido",J28*1,IF(BF28="Disponible",J28*0,IF(BF28="Enganche Completado",J28*1,IF(BF28="Superávit de Enganche",J28*1,0)))) -> 48242 | BE28: =IF(D28=0,J28*0,BD28-AX28) -> 26621 | BF28: =IF(D28=0,"Apartamento Disponible",IF(D28>1,"Vendido",0)) -> Vendido | BG28: =IF(AND(BF28="Vendido",E28>=0,AZ28=0),"Enganche Completado",IF(AND(BF28="Vendido",E28>=0,AZ28>0),"Superávit de Enganche",IF(AND(BF28="Apartamento Disponible",E28=0,AZ28=0),"Disponible","Cliente Atrasado"))) -> Cliente Atrasado | BI28: =COUNTIF(L28:AT28,">0.01") -> 0 | BJ28: =IF(AND(BG28="Cliente Atrasado",COUNTIF(L28:AT28,"<0.01")),DATEDIF(E28,AT$4+1,"m"),0) -> 0 | BK28: Dep. Reserva | BM28: Sin promesa firmada
B29: 404 | C29: Ricardo O. | D29: Nancy Andrea Ovalle Valladares | E29: 44963 | F29: B2 | G29: 655000 | H29: 655000 | I29: =+G29-H29 -> 0 | J29: 65500 | K29: 4.PLAN DE PAGOS | L29: 0 | M29: 0 | N29: 0 | O29: 0 | P29: 0 | Q29: 0 | R29: 0 | S29: 0 | T29: 5000 | U29: 3500 | V29: 3617.76 | W29: 3500 | X29: 3500 | Y29: 3500 | Z29: 3500 | AA29: 7000 | AB29: 0 | AC29: 7000 | AD29: 3500 | AE29: 3500 | AF29: 0 | AG29: 3500 | AH29: 3500 | AI29: 3500 | AJ29: 3500 | AK29: 3500 | AL29: 882.24 | AM29: 0 | AN29: 0 | AO29: 0 | AP29: 0 | AQ29: 0 | AR29: 0 | AS29: 0 | AX29: =SUM(L29:AV29) -> 65500 | AY29: =IFERROR((+AX29/BD29),0) -> 1 | AZ29: =+AX29-BD29 -> 0 | BA29: =IFERROR((+AZ29/BD29),0) -> 0 | BB29: =+H29-AX29 -> 589500 | BC29: =+BB29/H29 -> 0.9 | BD29: =IF(BF29="Vendido",J29*1,IF(BF29="Disponible",J29*0,IF(BF29="Enganche Completado",J29*1,IF(BF29="Superávit de Enganche",J29*1,0)))) -> 65500 | BE29: =IF(D29=0,J29*0,BD29-AX29) -> 0 | BF29: =IF(D29=0,"Apartamento Disponible",IF(D29>1,"Vendido",0)) -> Vendido | BG29: =IF(AND(BF29="Vendido",E29>=0,AZ29=0),"Enganche Completado",IF(AND(BF29="Vendido",E29>=0,AZ29>0),"Superávit de Enganche",IF(AND(BF29="Apartamento Disponible",E29=0,AZ29=0),"Disponible","Cliente Atrasado"))) -> Enganche Completado | BI29: =COUNTIF(L29:AT29,">0.01") -> 17 | BJ29: =IF(AND(BG29="Cliente Atrasado",COUNTIF(L29:AT29,"<0.01")),DATEDIF(E29,AT$4+1,"m"),0) -> 0
B30: 405 | C30: Noemi M. | D30: Lester Eduardo Velasquez Dubon. | E30: 44956 | F30: B2 | G30: 655000 | H30: 655000 | I30: =+G30-H30 -> 0 | J30: 414500 | K30: 4.PLAN DE PAGOS | L30: 0 | M30: 0 | N30: 0 | O30: 0 | P30: 0 | Q30: 0 | R30: 0 | S30: 5000 | T30: 3500 | U30: 3500 | V30: 3500 | W30: 3500 | X30: 3500 | Y30: 3500 | Z30: 3500 | AA30: 3500 | AB30: 3500 | AC30: 3500 | AD30: 3500 | AE30: 3500 | AF30: 3500 | AG30: 3500 | AH30: 3500 | AI30: 3500 | AJ30: 3500 | AK30: 0 | AL30: 0 | AM30: 0 | AN30: 0 | AO30: 0 | AP30: 0 | AQ30: =252200+88000+74800+500 -> 415500 | AR30: 0 | AS30: 0 | AX30: =SUM(L30:AV30) -> 480000 | AY30: =IFERROR((+AX30/BD30),0) -> 1.1580217 | AZ30: =+AX30-BD30 -> 65500 | BA30: =IFERROR((+AZ30/BD30),0) -> 0.15802171 | BB30: =+H30-AX30 -> 175000 | BC30: =+BB30/H30 -> 0.26717557 | BD30: =IF(BF30="Vendido",J30*1,IF(BF30="Disponible",J30*0,IF(BF30="Enganche Completado",J30*1,IF(BF30="Superávit de Enganche",J30*1,0)))) -> 414500 | BE30: =IF(D30=0,J30*0,BD30-AX30) -> -65500 | BF30: =IF(D30=0,"Apartamento Disponible",IF(D30>1,"Vendido",0)) -> Vendido | BG30: =IF(AND(BF30="Vendido",E30>=0,AZ30=0),"Enganche Completado",IF(AND(BF30="Vendido",E30>=0,AZ30>0),"Superávit de Enganche",IF(AND(BF30="Apartamento Disponible",E30=0,AZ30=0),"Disponible","Cliente Atrasado"))) -> Superávit de Enganche | BI30: =COUNTIF(L30:AT30,">0.01") -> 19 | BJ30: =IF(AND(BG30="Cliente Atrasado",COUNTIF(L30:AT30,"<0.01")),DATEDIF(E30,AT$4+1,"m"),0) -> 0
B31: 406 | C31: Paula H. | D31: Gerson Merari Tubac Tepaz | E31: 45625 | F31: A3 | G31: 964442 | H31: 948800 | I31: =+G31-H31 -> 15642 | J31: 49500 | K31: 4.PLAN DE PAGOS | L31: 0 | M31: 0 | N31: 0 | O31: 0 | P31: 0 | Q31: 0 | R31: 0 | S31: 0 | T31: 0 | U31: 0 | V31: 0 | W31: 0 | X31: 0 | Y31: 0 | AA31: 0 | AB31: 0 | AC31: 0 | AD31: 0 | AE31: 0 | AF31: 0 | AG31: 0 | AH31: 0 | AI31: 0 | AJ31: 0 | AK31: 0 | AL31: 0 | AN31: 0 | AO31: =5000+22250 -> 27250 | AP31: 22250 | AQ31: 0 | AR31: 0 | AS31: 0 | AX31: =SUM(L31:AV31) -> 49500 | AY31: =IFERROR((+AX31/BD31),0) -> 1 | AZ31: =+AX31-BD31 -> 0 | BA31: =IFERROR((+AZ31/BD31),0) -> 0 | BB31: =+H31-AX31 -> 899300 | BC31: =+BB31/H31 -> 0.94782884 | BD31: =IF(BF31="Vendido",J31*1,IF(BF31="Disponible",J31*0,IF(BF31="Enganche Completado",J31*1,IF(BF31="Superávit de Enganche",J31*1,0)))) -> 49500 | BE31: =IF(D31=0,J31*0,BD31-AX31) -> 0 | BF31: =IF(D31=0,"Apartamento Disponible",IF(D31>1,"Vendido",0)) -> Vendido | BG31: =IF(AND(BF31="Vendido",E31>=0,AZ31=0),"Enganche Completado",IF(AND(BF31="Vendido",E31>=0,AZ31>0),"Superávit de Enganche",IF(AND(BF31="Apartamento Disponible",E31=0,AZ31=0),"Disponible","Cliente Atrasado"))) -> Enganche Completado | BI31: =COUNTIF(L31:AT31,">0.01") -> 2 | BJ31: =IF(AND(BG31="Cliente Atrasado",COUNTIF(L31:AT31,"<0.01")),DATEDIF(E31,AT$4+1,"m"),0) -> 0
